Workbook

Sheet Raw Data
A1: transaction_id | B1: player_id | C1: country | D1: provider | E1: amount_eur | F1: status | G1: approval_status | H1: response_time_sec | I1: chargeback | J1: device | K1: card_bin | L1: risk_score | M1: fraud_flag | N1: vpn_detected | O1: multi_account | P1: bonus_abuse | Q1: account_takeover | R1: timestamp | S1: failure_reason
A2: TX008257 | B2: PL02937 | C2: Poland | D2: Provider_C | E2: 222.73 | F2: Success | G2: Approved | H2: 1.76 | I2: 0 | J2: Android | K2: 476285 | L2: 13 | M2: 0 | N2: 0 | O2: 0 | P2: 0 | Q2: 0 | R2: 2025-02-15 21:54:45
A3: TX005248 | B3: PL02620 | C3: UK | D3: Provider_A | E3: 1803.37 | F3: Success | G3: Approved | H3: 0.61 | I3: 0 | J3: iPhone | K3: 400950 | L3: 12 | M3: 0 | N3: 0 | O3: 0 | P3: 0 | Q3: 0 | R3: 2025-12-12 11:31:03
A4: TX001150 | B4: PL00373 | C4: Brazil | D4: Provider_A | E4: 84.28 | F4: Success | G4: Approved | H4: 7.83 | I4: 0 | J4: Android | K4: 544005 | L4: 17 | M4: 0 | N4: 0 | O4: 0 | P4: 0 | Q4: 0 | R4: 2025-08-22 16:39:08
A5: TX008621 | B5: PL00108 | C5: UK | D5: Provider_A | E5: 417.4 | F5: Failed | G5: Declined | H5: 2.01 | I5: 0 | J5: iPhone | K5: 511811 | L5: 74 | M5: 1 | N5: 1 | O5: 1 | P5: 0 | Q5: 0 | R5: 2025-09-02 20:55:09
A6: TX000108 | B6: PL02891 | C6: Germany | D6: Provider_C | E6: 244.5 | F6: Success | G6: Approved | H6: 10.19 | I6: 0 | J6: iPhone | K6: 554712 | L6: 11 | M6: 0 | N6: 0 | O6: 0 | P6: 0 | Q6: 0 | R6: 2025-05-30 22:30:53
A7: TX008324 | B7: PL01261 | C7: Germany | D7: Provider_C | E7: 748.62 | F7: Failed | G7: Approved | H7: 4.07 | I7: 0 | J7: Desktop | K7: 528044 | L7: 21 | M7: 0 | N7: 0 | O7: 0 | P7: 0 | Q7: 0 | R7: 2025-10-15 00:08:38 | S7: Provider-side timeout — bank approved, gateway failed
A8: TX007291 | B8: PL02792 | C8: Canada | D8: Provider_D | E8: 1195.34 | F8: Abandoned | G8: Approved | H8: 16.45 | I8: 0 | J8: Android | K8: 477242 | L8: 18 | M8: 0 | N8: 0 | O8: 0 | P8: 0 | Q8: 0 | R8: 2025-01-10 12:17:59 | S8: Session timeout — bank pre-authorized, player abandoned
A9: TX008591 | B9: PL00347 | C9: Portugal | D9: Provider_C | E9: 352.66 | F9: Success | G9: Approved | H9: 8.18 | I9: 0 | J9: Desktop | K9: 540528 | L9: 15 | M9: 0 | N9: 0 | O9: 0 | P9: 0 | Q9: 0 | R9: 2025-07-08 11:42:26
A10: TX002983 | B10: PL02109 | C10: UK | D10: Provider_A | E10: 790.55 | F10: Success | G10: Approved | H10: 4.62 | I10: 0 | J10: iPhone | K10: 521637 | L10: 19 | M10: 0 | N10: 0 | O10: 0 | P10: 0 | Q10: 0 | R10: 2025-07-08 12:00:13
A11: TX001218 | B11: PL01906 | C11: Germany | D11: Provider_C | E11: 163.95 | F11: Success | G11: Approved | H11: 8.74 | I11: 0 | J11: iPhone | K11: 416847 | L11: 21 | M11: 0 | N11: 0 | O11: 0 | P11: 0 | Q11: 0 | R11: 2025-11-13 20:39:59
A12: TX000319 | B12: PL01071 | C12: Germany | D12: Provider_B | E12: 1052.49 | F12: Success | G12: Approved | H12: 7.26 | I12: 0 | J12: Desktop | K12: 511451 | L12: 24 | M12: 0 | N12: 0 | O12: 0 | P12: 0 | Q12: 0 | R12: 2025-10-29 00:34:37
A13: TX007801 | B13: PL02187 | C13: Canada | D13: Provider_D | E13: 198.4 | F13: Success | G13: Approved | H13: 11.41 | I13: 0 | J13: iPhone | K13: 419645 | L13: 20 | M13: 0 | N13: 0 | O13: 0 | P13: 0 | Q13: 0 | R13: 2025-12-19 04:11:36
A14: TX003282 | B14: PL02542 | C14: Brazil | D14: Provider_A | E14: 165.84 | F14: Success | G14: Approved | H14: 1.47 | I14: 0 | J14: Desktop | K14: 434778 | L14: 21 | M14: 0 | N14: 0 | O14: 0 | P14: 0 | Q14: 0 | R14: 2025-03-31 11:25:58
A15: TX009751 | B15: PL02528 | C15: Canada | D15: Provider_D | E15: 387.8 | F15: Success | G15: Approved | H15: 8.3 | I15: 0 | J15: Android | K15: 405687 | L15: 13 | M15: 0 | N15: 0 | O15: 0 | P15: 0 | Q15: 0 | R15: 2025-10-13 05:52:14
A16: TX004002 | B16: PL01050 | C16: Germany | D16: Provider_D | E16: 769.65 | F16: Failed | G16: Declined | H16: 11.01 | I16: 0 | J16: Desktop | K16: 420779 | L16: 23 | M16: 0 | N16: 0 | O16: 0 | P16: 0 | Q16: 0 | R16: 2025-07-15 21:45:07
A17: TX007468 | B17: PL02248 | C17: UK | D17: Provider_B | E17: 2145.07 | F17: Success | G17: Approved | H17: 8.5 | I17: 0 | J17: iPhone | K17: 422103 | L17: 14 | M17: 0 | N17: 0 | O17: 0 | P17: 0 | Q17: 0 | R17: 2025-04-19 01:37:54
A18: TX004380 | B18: PL00395 | C18: Poland | D18: Provider_D | E18: 536.4 | F18: Success | G18: Approved | H18: 17.27 | I18: 0 | J18: iPhone | K18: 513510 | L18: 13 | M18: 0 | N18: 0 | O18: 0 | P18: 0 | Q18: 0 | R18: 2025-07-11 21:24:54
A19: TX001419 | B19: PL00907 | C19: Germany | D19: Provider_C | E19: 69.52 | F19: Abandoned | G19: Approved | H19: 11.79 | I19: 0 | J19: iPhone | K19: 510469 | L19: 41 | M19: 0 | N19: 0 | O19: 0 | P19: 1 | Q19: 0 | R19: 2025-08-07 22:42:42 | S19: Session timeout — bank pre-authorized, player abandoned
A20: TX001513 | B20: PL02532 | C20: Netherlands | D20: Provider_C | E20: 589.75 | F20: Failed | G20: Declined | H20: 7.53 | I20: 0 | J20: iPhone | K20: 551219 | L20: 21 | M20: 0 | N20: 0 | O20: 0 | P20: 0 | Q20: 0 | R20: 2025-08-15 22:47:00
A21: TX006171 | B21: PL01681 | C21: Poland | D21: Provider_D | E21: 366.16 | F21: Success | G21: Approved | H21: 17.63 | I21: 0 | J21: Android | K21: 500255 | L21: 24 | M21: 0 | N21: 0 | O21: 0 | P21: 0 | Q21: 0 | R21: 2025-01-10 21:46:56
A22: TX004424 | B22: PL02039 | C22: Poland | D22: Provider_B | E22: 566.75 | F22: Success | G22: Approved | H22: 0.91 | I22: 0 | J22: iPhone | K22: 406942 | L22: 22 | M22: 0 | N22: 0 | O22: 0 | P22: 0 | Q22: 0 | R22: 2025-12-24 15:33:39
A23: TX004129 | B23: PL02584 | C23: UK | D23: Provider_A | E23: 381.3 | F23: Success | G23: Approved | H23: 8.41 | I23: 0 | J23: Desktop | K23: 524110 | L23: 13 | M23: 0 | N23: 0 | O23: 0 | P23: 0 | Q23: 0 | R23: 2025-09-28 13:10:40
A24: TX003543 | B24: PL00962 | C24: UK | D24: Provider_C | E24: 224.72 | F24: Success | G24: Approved | H24: 6.84 | I24: 0 | J24: iPhone | K24: 414049 | L24: 15 | M24: 0 | N24: 0 | O24: 0 | P24: 0 | Q24: 0 | R24: 2025-08-23 16:49:36
A25: TX001497 | B25: PL01869 | C25: Austria | D25: Provider_D | E25: 1046.44 | F25: Success | G25: Approved | H25: 10.47 | I25: 0 | J25: Android | K25: 497904 | L25: 48 | M25: 0 | N25: 0 | O25: 1 | P25: 0 | Q25: 0 | R25: 2025-06-27 10:31:14
A26: TX001878 | B26: PL01557 | C26: Portugal | D26: Provider_B | E26: 984.85 | F26: Abandoned | G26: Approved | H26: 1.11 | I26: 0 | J26: Android | K26: 456238 | L26: 24 | M26: 0 | N26: 0 | O26: 0 | P26: 0 | Q26: 0 | R26: 2025-03-21 14:21:34 | S26: Session timeout — bank pre-authorized, player abandoned
A27: TX007739 | B27: PL00577 | C27: Germany | D27: Provider_D | E27: 135.49 | F27: Success | G27: Approved | H27: 13.31 | I27: 0 | J27: Android | K27: 405697 | L27: 10 | M27: 0 | N27: 0 | O27: 0 | P27: 0 | Q27: 0 | R27: 2025-06-30 04:01:08
A28: TX001057 | B28: PL01152 | C28: Spain | D28: Provider_C | E28: 1562.31 | F28: Abandoned | G28: Declined | H28: 7.71 | I28: 0 | J28: iPhone | K28: 477810 | L28: 59 | M28: 1 | N28: 0 | O28: 0 | P28: 0 | Q28: 1 | R28: 2025-07-21 20:26:02
A29: TX002690 | B29: PL02895 | C29: Canada | D29: Provider_B | E29: 225.44 | F29: Success | G29: Approved | H29: 6.64 | I29: 0 | J29: Android | K29: 452353 | L29: 12 | M29: 0 | N29: 0 | O29: 0 | P29: 0 | Q29: 0 | R29: 2025-12-09 17:21:00
A30: TX009080 | B30: PL02303 | C30: Sweden | D30: Provider_B | E30: 249.56 | F30: Failed | G30: Declined | H30: 11.24 | I30: 0 | J30: Android | K30: 442160 | L30: 14 | M30: 0 | N30: 0 | O30: 0 | P30: 0 | Q30: 0 | R30: 2025-05-29 18:19:11
A31: TX001834 | B31: PL01664 | C31: UK | D31: Provider_A | E31: 272.25 | F31: Success | G31: Approved | H31: 2.47 | I31: 0 | J31: Desktop | K31: 440781 | L31: 12 | M31: 0 | N31: 0 | O31: 0 | P31: 0 | Q31: 0 | R31: 2025-03-21 06:17:15
A32: TX006095 | B32: PL02671 | C32: Germany | D32: Provider_D | E32: 320.14 | F32: Failed | G32: Declined | H32: 19.16 | I32: 0 | J32: Desktop | K32: 511738 | L32: 15 | M32: 0 | N32: 0 | O32: 0 | P32: 0 | Q32: 0 | R32: 2025-07-22 09:13:58
A33: TX005791 | B33: PL00630 | C33: Brazil | D33: Provider_D | E33: 223.6 | F33: Success | G33: Approved | H33: 8.09 | I33: 0 | J33: Android | K33: 455493 | L33: 19 | M33: 0 | N33: 0 | O33: 0 | P33: 0 | Q33: 0 | R33: 2025-12-30 17:09:01
A34: TX007609 | B34: PL00835 | C34: Germany | D34: Provider_C | E34: 66.27 | F34: Success | G34: Approved | H34: 7.94 | I34: 0 | J34: Desktop | K34: 405243 | L34: 18 | M34: 0 | N34: 0 | O34: 0 | P34: 0 | Q34: 0 | R34: 2025-05-02 19:45:38
A35: TX007200 | B35: PL01579 | C35: Austria | D35: Provider_B | E35: 438.83 | F35: Success | G35: Approved | H35: 2.82 | I35: 0 | J35: iPad | K35: 552019 | L35: 10 | M35: 0 | N35: 0 | O35: 0 | P35: 0 | Q35: 0 | R35: 2025-01-20 20:06:14
A36: TX008181 | B36: PL02760 | C36: Sweden | D36: Provider_C | E36: 288.84 | F36: Success | G36: Approved | H36: 7.13 | I36: 0 | J36: Desktop | K36: 492882 | L36: 14 | M36: 0 | N36: 0 | O36: 0 | P36: 0 | Q36: 0 | R36: 2025-12-20 17:09:05
A37: TX002056 | B37: PL01469 | C37: Poland | D37: Provider_C | E37: 875.11 | F37: Failed | G37: Approved | H37: 8.17 | I37: 0 | J37: Desktop | K37: 472210 | L37: 17 | M37: 0 | N37: 0 | O37: 0 | P37: 0 | Q37: 0 | R37: 2025-02-19 18:56:29 | S37: Provider-side timeout — bank approved, gateway failed
A38: TX003606 | B38: PL02498 | C38: Brazil | D38: Provider_A | E38: 344.01 | F38: Failed | G38: Approved | H38: 3.52 | I38: 0 | J38: Desktop | K38: 495812 | L38: 21 | M38: 0 | N38: 0 | O38: 0 | P38: 0 | Q38: 0 | R38: 2025-03-24 00:56:01 | S38: Provider-side timeout — bank approved, gateway failed
A39: TX002877 | B39: PL02309 | C39: Portugal | D39: Provider_C | E39: 231.81 | F39: Success | G39: Approved | H39: 8.07 | I39: 0 | J39: iPhone | K39: 454724 | L39: 11 | M39: 0 | N39: 0 | O39: 0 | P39: 0 | Q39: 0 | R39: 2025-02-21 21:36:37
A40: TX009233 | B40: PL00048 | C40: Germany | D40: Provider_A | E40: 1177.06 | F40: Success | G40: Approved | H40: 11.59 | I40: 0 | J40: Desktop | K40: 542702 | L40: 21 | M40: 0 | N40: 0 | O40: 0 | P40: 0 | Q40: 0 | R40: 2025-10-06 17:05:04
...

Sheet Analysis
A1: iGaming Payment & Fraud Analysis | Risk Dashboard | 2025
B4: Row Labels | C4: Count of transaction_id | E4: Row Labels | F4: Count of transaction_id
B5: Provider_A | C5: 3001 | E5: Austria | F5: 196
B6: Provider_B | C6: 2793 | E6: Brazil | F6: 1250
B7: Provider_C | C7: 2513 | E7: Canada | F7: 788 | J7: SR | M7: Сountry SR | Q7: ApporaleRate | S7: Chargeback
B8: Provider_D | C8: 1748 | E8: Germany | F8: 1823 | H8: ALL | J8: =COUNTIFS('Raw Data'!F:F,"Success")/(COUNTA('Raw Data'!C:C)-1) -> 0.64863252 | L8: Austria | M8: =COUNTIFS('Raw Data'!C:C,"Austria",'Raw Data'!F:F,"Success")/COUNTIFS('Raw Data'!C:C,"Austria") -> 0.71428571 | Q8: =COUNTIFS('Raw Data'!G:G,"approved")/(COUNTA('Raw Data'!G:G)-1) -> 0.75574341 | S8: =COUNTIFS('Raw Data'!I:I,1)/COUNTIFS('Raw Data'!F:F,"Success") -> 0.0065930696
B9: Grand Total | C9: 10055 | E9: Netherlands | F9: 401 | H9: Provider_C | J9: =COUNTIFS('Raw Data'!D:D,"Provider_C",'Raw Data'!F:F,"Success")/COUNTIFS('Raw Data'!D:D,"Provider_C") -> 0.73418225 | L9: Brazil | M9: =COUNTIFS('Raw Data'!C:C,"Brazil",'Raw Data'!F:F,"Success")/COUNTIFS('Raw Data'!C:C,"Brazil") -> 0.5712 | O9: Provider_C | Q9: =COUNTIFS('Raw Data'!D:D,"Provider_C",'Raw Data'!G:G,"Approved")/COUNTIFS('Raw Data'!D:D,"PROVIDER_C") -> 0.81575806
E10: Poland | F10: 1402 | H10: Provider_A | J10: =COUNTIFS('Raw Data'!D:D,"Provider_A",'Raw Data'!F:F,"Success")/COUNTIFS('Raw Data'!D:D,"Provider_A") -> 0.69743419 | L10: Canada | M10: =COUNTIFS('Raw Data'!C:C,"Canada",'Raw Data'!F:F,"Success")/COUNTIFS('Raw Data'!C:C,"Canada") -> 0.66878173 | O10: Provider_A | Q10: =COUNTIFS('Raw Data'!D:D,"Provider_A",'Raw Data'!G:G,"Approved")/COUNTIFS('Raw Data'!D:D,"PROVIDER_A") -> 0.79240253
E11: Portugal | F11: 910 | H11: Provider_D | J11: =COUNTIFS('Raw Data'!D:D,"Provider_D",'Raw Data'!F:F,"Success")/COUNTIFS('Raw Data'!D:D,"Provider_D") -> 0.4576659 | L11: Germany | M11: =COUNTIFS('Raw Data'!C:C,"Germany",'Raw Data'!F:F,"Success")/COUNTIFS('Raw Data'!C:C,"Germany") -> 0.65112452 | O11: Provider_D | Q11: =COUNTIFS('Raw Data'!D:D,"Provider_D",'Raw Data'!G:G,"Approved")/COUNTIFS('Raw Data'!D:D,"PROVIDER_D") -> 0.61727689
B12: Row Labels | C12: Average of response_time_sec | E12: Spain | F12: 1121 | H12: Provider_B | J12: =COUNTIFS('Raw Data'!D:D,"Provider_B",'Raw Data'!F:F,"Success")/COUNTIFS('Raw Data'!D:D,"Provider_B") -> 0.63873971 | L12: Netherlands | M12: =COUNTIFS('Raw Data'!C:C,"Netherlands",'Raw Data'!F:F,"Success")/COUNTIFS('Raw Data'!C:C,"Netherlands") -> 0.64588529 | O12: Provider_B | Q12: =COUNTIFS('Raw Data'!D:D,"Provider_B",'Raw Data'!G:G,"Approved")/COUNTIFS('Raw Data'!D:D,"PROVIDER_B") -> 0.7490154
B13: Provider_A | C13: 6.1437954 | E13: Sweden | F13: 596 | L13: Poland | M13: =COUNTIFS('Raw Data'!C:C,"Poland",'Raw Data'!F:F,"Success")/COUNTIFS('Raw Data'!C:C,"Poland") -> 0.68473609
B14: Provider_B | C14: 6.2828894 | E14: UK | F14: 1568 | L14: Portugal | M14: =COUNTIFS('Raw Data'!C:C,"Portugal",'Raw Data'!F:F,"Success")/COUNTIFS('Raw Data'!C:C,"Portugal") -> 0.65934066
B15: Provider_C | C15: 6.1692002 | E15: Grand Total | F15: 10055 | L15: Spain | M15: =COUNTIFS('Raw Data'!C:C,"Spain",'Raw Data'!F:F,"Success")/COUNTIFS('Raw Data'!C:C,"Spain") -> 0.65744871
B16: Provider_D | C16: 13.884508 | L16: Sweden | M16: =COUNTIFS('Raw Data'!C:C,"Sweden",'Raw Data'!F:F,"Success")/COUNTIFS('Raw Data'!C:C,"Sweden") -> 0.64261745
B17: Grand Total | C17: 7.5344565 | L17: UK | M17: =COUNTIFS('Raw Data'!C:C,"UK",'Raw Data'!F:F,"Success")/COUNTIFS('Raw Data'!C:C,"UK") -> 0.64732143
H19: status | I19: (All) | O19: country | P19: Brazil
B20: Row Labels | C20: Count of transaction_id
B21: PL00001 | C21: 27 | E21: Row Labels | F21: Sum of chargeback | H21: Count of transaction_id | I21: Column Labels | O21: Sum of chargeback | P21: Column Labels
B22: PL00387 | C22: 13 | E22: Austria | F22: 0 | H22: Row Labels | I22: Provider_A | J22: Provider_C | K22: Provider_D | L22: Grand Total | O22: Row Labels | P22: 1 | Q22: Grand Total
B23: PL01178 | C23: 12 | E23: Brazil | F23: 30 | H23: 400719 | I23: 1 | L23: 1 | O23: PL01008 | P23: 1 | Q23: 1
B24: PL02780 | C24: 11 | E24: Canada | F24: 0 | H24: 403418 | I24: 1 | L24: 1 | O24: PL01033 | P24: 1 | Q24: 1
B25: PL02029 | C25: 11 | E25: Germany | F25: 4 | H25: 404344 | I25: 1 | L25: 1 | O25: PL01046 | P25: 1 | Q25: 1
B26: PL01818 | C26: 10 | E26: Netherlands | F26: 0 | H26: 413157 | I26: 1 | L26: 1 | O26: PL01048 | P26: 1 | Q26: 1
B27: PL00898 | C27: 10 | E27: Poland | F27: 0 | H27: 417222 | I27: 1 | L27: 1 | O27: PL01145 | P27: 1 | Q27: 1
B28: PL02602 | C28: 10 | E28: Portugal | F28: 2 | H28: 417397 | I28: 1 | L28: 1 | O28: PL01194 | P28: 1 | Q28: 1
B29: PL00199 | C29: 10 | E29: Spain | F29: 1 | H29: 420266 | I29: 1 | L29: 1 | O29: PL01197 | P29: 1 | Q29: 1
B30: PL00637 | C30: 10 | E30: Sweden | F30: 2 | H30: 421778 | I30: 1 | L30: 1 | O30: PL01256 | P30: 1 | Q30: 1
B31: PL01316 | C31: 10 | E31: UK | F31: 4 | H31: 422754 | I31: 1 | L31: 1 | O31: PL01344 | P31: 1 | Q31: 1
B32: Grand Total | C32: 134 | E32: Grand Total | F32: 43 | H32: 427627 | I32: 1 | L32: 1 | O32: PL01383 | P32: 1 | Q32: 1
H33: 427713 | I33: 1 | L33: 1 | O33: PL01384 | P33: 1 | Q33: 1
H34: 427987 | I34: 1 | L34: 1 | O34: PL01428 | P34: 1 | Q34: 1
H35: 441743 | I35: 1 | L35: 1 | O35: PL01440 | P35: 1 | Q35: 1
H36: 442000 | I36: 1 | L36: 1 | O36: PL01443 | P36: 1 | Q36: 1
H37: 443079 | I37: 1 | L37: 1 | O37: PL01459 | P37: 1 | Q37: 1
H38: 450907 | I38: 1 | L38: 1 | O38: PL01492 | P38: 1 | Q38: 1
H39: 455835 | I39: 1 | L39: 1 | O39: PL01494 | P39: 1 | Q39: 1
H40: 459571 | I40: 1 | L40: 1 | O40: PL01495 | P40: 1 | Q40: 1
H41: 462737 | I41: 1 | L41: 1 | O41: PL01539 | P41: 1 | Q41: 1
H42: 471122 | I42: 1 | L42: 1 | O42: PL01562 | P42: 1 | Q42: 1
H43: 475780 | I43: 1 | L43: 1 | O43: PL01596 | P43: 1 | Q43: 1
...

Sheet Fraud Investigation
A1: transaction_id | B1: player_id | C1: country | D1: provider | E1: amount_eur | F1: status | G1: approval_status | H1: response_time_sec | I1: chargeback | J1: device | K1: card_bin | L1: risk_score | M1: fraud_flag | N1: vpn_detected | O1: multi_account | P1: bonus_abuse | Q1: account_takeover | R1: timestamp
A2: TX000377 | B2: PL00001 | C2: Poland | D2: Provider_C | E2: 156.72 | F2: Abandoned | G2: Declined | H2: 8.26 | I2: 0 | J2: Desktop | K2: 550914 | L2: 11 | M2: 0 | N2: 0 | O2: 0 | P2: 0 | Q2: 0 | R2: 2025-02-08 21:19:10 | V2: Player ID | W2: PL00001
A3: TX_ATK0 | B3: PL00001 | C3: Germany | D3: Provider_A | E3: 4.83 | F3: Success | G3: Approved | H3: 1.42 | I3: 0 | J3: Desktop | K3: 422754 | L3: 85 | M3: 1 | N3: 0 | O3: 0 | P3: 0 | Q3: 0 | R3: 2025-06-15 02:00:00 | V3: Total Transactions | W3: 27
A4: TX_ATK1 | B4: PL00001 | C4: Germany | D4: Provider_A | E4: 1.38 | F4: Success | G4: Approved | H4: 1.78 | I4: 0 | J4: Desktop | K4: 443079 | L4: 85 | M4: 1 | N4: 0 | O4: 0 | P4: 0 | Q4: 0 | R4: 2025-06-15 02:02:00 | V4: Attack Transactions | W4: 25
A5: TX_ATK2 | B5: PL00001 | C5: Germany | D5: Provider_A | E5: 2.65 | F5: Success | G5: Approved | H5: 1.48 | I5: 0 | J5: Desktop | K5: 413157 | L5: 85 | M5: 1 | N5: 0 | O5: 0 | P5: 0 | Q5: 0 | R5: 2025-06-15 02:04:00 | V5: Successful | W5: 24
A6: TX_ATK3 | B6: PL00001 | C6: Germany | D6: Provider_A | E6: 3.39 | F6: Success | G6: Approved | H6: 1.45 | I6: 0 | J6: Desktop | K6: 475780 | L6: 85 | M6: 1 | N6: 0 | O6: 0 | P6: 0 | Q6: 0 | R6: 2025-06-15 02:06:00 | V6: Abandoned | W6: 1
A7: TX_ATK4 | B7: PL00001 | C7: Germany | D7: Provider_A | E7: 2.92 | F7: Success | G7: Approved | H7: 1.02 | I7: 0 | J7: Desktop | K7: 421778 | L7: 85 | M7: 1 | N7: 0 | O7: 0 | P7: 0 | Q7: 0 | R7: 2025-06-15 02:08:00 | V7: Normal Transactions | W7: 2 (prior history)
A8: TX_ATK5 | B8: PL00001 | C8: Germany | D8: Provider_A | E8: 2.45 | F8: Success | G8: Approved | H8: 0.88 | I8: 0 | J8: Desktop | K8: 488014 | L8: 85 | M8: 1 | N8: 0 | O8: 0 | P8: 0 | Q8: 0 | R8: 2025-06-15 02:10:00 | V8: Timeframe of Attack | W8: 02:00 — 02:48, June 15 2025
A9: TX_ATK6 | B9: PL00001 | C9: Germany | D9: Provider_A | E9: 1.24 | F9: Success | G9: Approved | H9: 1.3 | I9: 0 | J9: Desktop | K9: 427627 | L9: 85 | M9: 1 | N9: 0 | O9: 0 | P9: 0 | Q9: 0 | R9: 2025-06-15 02:12:00 | V9: Avg Amount | W9: =AVERAGEIF('Raw Data'!B:B,"PL00001",'Raw Data'!E:E) -> 29.995926
A10: TX_ATK7 | B10: PL00001 | C10: Germany | D10: Provider_A | E10: 2.46 | F10: Success | G10: Approved | H10: 1.86 | I10: 0 | J10: Desktop | K10: 477620 | L10: 85 | M10: 1 | N10: 0 | O10: 0 | P10: 0 | Q10: 0 | R10: 2025-06-15 02:14:00 | V10: Avg Amount (Attack) | W10: =AVERAGE(H3:H27) -> 1.2292
A11: TX_ATK8 | B11: PL00001 | C11: Germany | D11: Provider_A | E11: 4.2 | F11: Success | G11: Approved | H11: 0.93 | I11: 0 | J11: Desktop | K11: 459571 | L11: 85 | M11: 1 | N11: 0 | O11: 0 | P11: 0 | Q11: 0 | R11: 2025-06-15 02:16:00 | V11: Unique BINs | W11: =COUNTIFS('Raw Data'!B:B,"PL00001") -> 27
A12: TX_ATK9 | B12: PL00001 | C12: Germany | D12: Provider_A | E12: 1.51 | F12: Success | G12: Approved | H12: 1.06 | I12: 0 | J12: Desktop | K12: 417222 | L12: 85 | M12: 1 | N12: 0 | O12: 0 | P12: 0 | Q12: 0 | R12: 2025-06-15 02:18:00 | V12: Risk Score | W12: =AVERAGEIF('Raw Data'!B:B,"PL00001",'Raw Data'!L:L) -> 80.777778
A13: TX_ATK10 | B13: PL00001 | C13: Germany | D13: Provider_A | E13: 3.79 | F13: Success | G13: Approved | H13: 0.68 | I13: 0 | J13: Desktop | K13: 417397 | L13: 85 | M13: 1 | N13: 0 | O13: 0 | P13: 0 | Q13: 0 | R13: 2025-06-15 02:20:00 | V13: Verdict | W13: Card Testing Attack
A14: TX_ATK11 | B14: PL00001 | C14: Germany | D14: Provider_A | E14: 1.08 | F14: Success | G14: Approved | H14: 1.98 | I14: 0 | J14: Desktop | K14: 482270 | L14: 85 | M14: 1 | N14: 0 | O14: 0 | P14: 0 | Q14: 0 | R14: 2025-06-15 02:22:00 | V14: Action Taken | W14: Account Frozen + BINs Blacklisted
A15: TX_ATK12 | B15: PL00001 | C15: Germany | D15: Provider_A | E15: 4.15 | F15: Success | G15: Approved | H15: 1.55 | I15: 0 | J15: Desktop | K15: 442000 | L15: 85 | M15: 1 | N15: 0 | O15: 0 | P15: 0 | Q15: 0 | R15: 2025-06-15 02:24:00
A16: TX_ATK13 | B16: PL00001 | C16: Germany | D16: Provider_A | E16: 1.02 | F16: Success | G16: Approved | H16: 1.35 | I16: 0 | J16: Desktop | K16: 462737 | L16: 85 | M16: 1 | N16: 0 | O16: 0 | P16: 0 | Q16: 0 | R16: 2025-06-15 02:26:00
A17: TX_ATK14 | B17: PL00001 | C17: Germany | D17: Provider_A | E17: 1.15 | F17: Success | G17: Approved | H17: 1.42 | I17: 0 | J17: Desktop | K17: 427713 | L17: 85 | M17: 1 | N17: 0 | O17: 0 | P17: 0 | Q17: 0 | R17: 2025-06-15 02:28:00
A18: TX_ATK15 | B18: PL00001 | C18: Germany | D18: Provider_A | E18: 1.02 | F18: Success | G18: Approved | H18: 1.44 | I18: 0 | J18: Desktop | K18: 471122 | L18: 85 | M18: 1 | N18: 0 | O18: 0 | P18: 0 | Q18: 0 | R18: 2025-06-15 02:30:00
A19: TX_ATK16 | B19: PL00001 | C19: Germany | D19: Provider_A | E19: 2.21 | F19: Success | G19: Approved | H19: 0.63 | I19: 0 | J19: Desktop | K19: 427987 | L19: 85 | M19: 1 | N19: 0 | O19: 0 | P19: 0 | Q19: 0 | R19: 2025-06-15 02:32:00
A20: TX_ATK17 | B20: PL00001 | C20: Germany | D20: Provider_A | E20: 4.54 | F20: Success | G20: Approved | H20: 0.89 | I20: 0 | J20: Desktop | K20: 441743 | L20: 85 | M20: 1 | N20: 0 | O20: 0 | P20: 0 | Q20: 0 | R20: 2025-06-15 02:34:00
A21: TX_ATK18 | B21: PL00001 | C21: Germany | D21: Provider_A | E21: 1.43 | F21: Success | G21: Approved | H21: 0.85 | I21: 0 | J21: Desktop | K21: 450907 | L21: 85 | M21: 1 | N21: 0 | O21: 0 | P21: 0 | Q21: 0 | R21: 2025-06-15 02:36:00
A22: TX_ATK19 | B22: PL00001 | C22: Germany | D22: Provider_A | E22: 4.2 | F22: Success | G22: Approved | H22: 1.71 | I22: 0 | J22: Desktop | K22: 420266 | L22: 85 | M22: 1 | N22: 0 | O22: 0 | P22: 0 | Q22: 0 | R22: 2025-06-15 02:38:00
A23: TX_ATK20 | B23: PL00001 | C23: Germany | D23: Provider_A | E23: 3.89 | F23: Success | G23: Approved | H23: 0.96 | I23: 0 | J23: Desktop | K23: 404344 | L23: 85 | M23: 1 | N23: 0 | O23: 0 | P23: 0 | Q23: 0 | R23: 2025-06-15 02:40:00
A24: TX_ATK21 | B24: PL00001 | C24: Germany | D24: Provider_A | E24: 1.81 | F24: Success | G24: Approved | H24: 1.89 | I24: 0 | J24: Desktop | K24: 403418 | L24: 85 | M24: 1 | N24: 0 | O24: 0 | P24: 0 | Q24: 0 | R24: 2025-06-15 02:42:00
A25: TX_ATK22 | B25: PL00001 | C25: Germany | D25: Provider_A | E25: 1.49 | F25: Success | G25: Approved | H25: 0.78 | I25: 0 | J25: Desktop | K25: 484951 | L25: 85 | M25: 1 | N25: 0 | O25: 0 | P25: 0 | Q25: 0 | R25: 2025-06-15 02:44:00
A26: TX_ATK23 | B26: PL00001 | C26: Germany | D26: Provider_A | E26: 4.38 | F26: Success | G26: Approved | H26: 0.77 | I26: 0 | J26: Desktop | K26: 400719 | L26: 85 | M26: 1 | N26: 0 | O26: 0 | P26: 0 | Q26: 0 | R26: 2025-06-15 02:46:00
... A28: TX008136 | B28: PL00001 | C28: Austria | D28: Provider_D | E28: 586.59 | F28: Success | G28: Approved | H28: 16.01 | I28: 0 | J28: Android | K28: 500860 | L28: 45 | M28: 0 | N28: 1 | O28: 0 | P28: 0 | Q28: 0 | R28: 2025-08-09 04:49:48

Sheet  Dashboard
B1: iGAMING PAYMENT & FRAUD ANALYSIS | RISK INTELLIGENCE DASHBOARD
B2: Dataset: 10,055 transactions | Providers: A/B/C/D | Countries: 10 | Period: Jan–Dec 2025
B4: KEY PERFORMANCE INDICATORS
B5: 📊 Total Transactions | D5: ✅ Success Rate | F5: 🏦 Approval Rate | I5: 💳 Chargeback Ratio | K5: 🚨 Fraud Rate | M5: 💰 Total Volume
B6: =COUNTA('Raw Data'!A:A)-1 -> 10055 | D6: =COUNTIFS('Raw Data'!F:F,"Success")/(COUNTA('Raw Data'!C:C)-1) -> 0.64863252 | F6: =COUNTIFS('Raw Data'!G:G,"approved")/(COUNTA('Raw Data'!G:G)-1) -> 0.75574341 | I6: =COUNTIFS('Raw Data'!I:I,1)/COUNTIFS('Raw Data'!F:F,"Success") -> 0.0065930696 | K6: =COUNTIF('Raw Data'!M:M,1)/(COUNTA('Raw Data'!A:A)-1) -> 0.038189955 | M6: =SUM('Raw Data'!E2:E100000) -> 5590233.7
B8: FRAUD SIGNAL BREAKDOWN
B9: 🚩 Fraud Flags | D9: 🌐 VPN Detected | F9: 👥 Multi-Account | I9: 🔑 Account Takeover | K9: 🎁 Bonus Abuse | M9: 💸 Chargebacks
B10: =COUNTIF('Raw Data'!M:M,1) -> 384 | D10: =COUNTIF('Raw Data'!N:N,1) -> 863 | F10: =COUNTIF('Raw Data'!O:O,1) -> 617 | I10: =COUNTIF('Raw Data'!Q:Q,1) -> 291 | K10: =COUNTIF('Raw Data'!P:P,1) -> 488 | M10: =COUNTIF('Raw Data'!I:I,1) -> 43
B11: =COUNTIFS('Raw Data'!M:M,1)/(COUNTA('Raw Data'!A:A)-1) -> 0.038189955 | D11: =COUNTIFS('Raw Data'!N:N,1)/(COUNTA('Raw Data'!A:A)-1) -> 0.085827946 | F11: =COUNTIFS('Raw Data'!O:O,1)/(COUNTA('Raw Data'!F:F)-1) -> 0.061362506 | I11: =COUNTIFS('Raw Data'!Q:Q,1)/(COUNTA('Raw Data'!F:F)-1) -> 0.028940825 | K11: =COUNTIFS('Raw Data'!P:P,1)/(COUNTA('Raw Data'!A:A)-1) -> 0.048533068 | M11: =COUNTIFS('Raw Data'!I:I,1)/COUNTIFS('Raw Data'!F:F,"Success") -> 0.0065930696
B13: PROVIDER PERFORMANCE ANALYSIS | I13: COUNTRY RISK ANALYSIS
B14: Row Labels | C14: Count of transaction_id | D14: Success Rate | E14: Approval Rate | F14: Chargeback Ratio | G14: Avg Response (s) | I14: Country | J14: Transactions | K14: Success Rate | L14: Chargeback Ratio | M14: Fraud Rate | N14: Total Volume (€)
B15: Provider_A | C15: 3001 | D15: =COUNTIFS('Raw Data'!D:D,"Provider_A",'Raw Data'!F:F,"Success")/COUNTIFS('Raw Data'!D:D,"Provider_A") -> 0.69743419 | E15: =COUNTIFS('Raw Data'!D:D,"Provider_A",'Raw Data'!G:G,"Approved")/COUNTIFS('Raw Data'!D:D,"PROVIDER_A") -> 0.79240253 | F15: =COUNTIFS('Raw Data'!D:D,"Provider_A",'Raw Data'!I:I,1)/COUNTIFS('Raw Data'!D:D,"Provider_A",'Raw Data'!F:F,"Success") -> 0.0019111323 | G15: =AVERAGEIF('Raw Data'!D:D,"Provider_A",'Raw Data'!H:H) -> 6.1437954 | I15: Austria | J15: 196 | K15: 0.71428571 | L15: =COUNTIFS('Raw Data'!C:C,"Austria",'Raw Data'!I:I,1)/COUNTIFS('Raw Data'!C:C,"Austria",'Raw Data'!F:F,"Success") -> 0 | M15: =COUNTIFS('Raw Data'!C:C,"Austria",'Raw Data'!M:M,1)/COUNTIFS('Raw Data'!C:C,"Austria") -> 0.015306122 | N15: =SUMIFS('Raw Data'!E:E,'Raw Data'!C:C,"Austria") -> 109935.02
B16: Provider_B | C16: 2793 | D16: =COUNTIFS('Raw Data'!D:D,"Provider_B",'Raw Data'!F:F,"Success")/COUNTIFS('Raw Data'!D:D,"Provider_B") -> 0.63873971 | E16: =COUNTIFS('Raw Data'!D:D,"Provider_B",'Raw Data'!G:G,"Approved")/COUNTIFS('Raw Data'!D:D,"PROVIDER_B") -> 0.7490154 | F16: =COUNTIFS('Raw Data'!D:D,"Provider_B",'Raw Data'!I:I,1)/COUNTIFS('Raw Data'!D:D,"Provider_B",'Raw Data'!F:F,"Success") -> 0.019618834 | G16: =AVERAGEIF('Raw Data'!D:D,"Provider_B",'Raw Data'!H:H) -> 6.2828894 | I16: Brazil | J16: 1250 | K16: 0.5712 | L16: =COUNTIFS('Raw Data'!C:C,"Brazil",'Raw Data'!I:I,1)/COUNTIFS('Raw Data'!C:C,"Brazil",'Raw Data'!F:F,"Success") -> 0.042016807 | M16: =COUNTIFS('Raw Data'!C:C,"Brazil",'Raw Data'!M:M,1)/COUNTIFS('Raw Data'!C:C,"Brazil") -> 0.0576 | N16: =SUMIFS('Raw Data'!E:E,'Raw Data'!C:C,"Brazil") -> 685493.64
B17: Provider_C | C17: 2513 | D17: =COUNTIFS('Raw Data'!D:D,"Provider_C",'Raw Data'!F:F,"Success")/COUNTIFS('Raw Data'!D:D,"Provider_C") -> 0.73418225 | E17: =COUNTIFS('Raw Data'!D:D,"Provider_C",'Raw Data'!G:G,"Approved")/COUNTIFS('Raw Data'!D:D,"PROVIDER_C") -> 0.81575806 | F17: =COUNTIFS('Raw Data'!D:D,"Provider_C",'Raw Data'!I:I,1)/COUNTIFS('Raw Data'!D:D,"Provider_C",'Raw Data'!F:F,"Success") -> 0.0021680217 | G17: =AVERAGEIF('Raw Data'!D:D,"Provider_C",'Raw Data'!H:H) -> 6.1692002 | I17: Canada | J17: 788 | K17: 0.66878173 | L17: =COUNTIFS('Raw Data'!C:C,"Canada",'Raw Data'!I:I,1)/COUNTIFS('Raw Data'!C:C,"Canada",'Raw Data'!F:F,"Success") -> 0 | M17: =COUNTIFS('Raw Data'!C:C,"Canada",'Raw Data'!M:M,1)/COUNTIFS('Raw Data'!C:C,"Canada") -> 0.029187817 | N17: =SUMIFS('Raw Data'!E:E,'Raw Data'!C:C,"Canada") -> 443212.87
B18: Provider_D | C18: 1748 | D18: =COUNTIFS('Raw Data'!D:D,"Provider_D",'Raw Data'!F:F,"Success")/COUNTIFS('Raw Data'!D:D,"Provider_D") -> 0.4576659 | E18: =COUNTIFS('Raw Data'!D:D,"Provider_D",'Raw Data'!G:G,"Approved")/COUNTIFS('Raw Data'!D:D,"PROVIDER_D") -> 0.61727689 | F18: =COUNTIFS('Raw Data'!D:D,"Provider_D",'Raw Data'!I:I,1)/COUNTIFS('Raw Data'!D:D,"Provider_D",'Raw Data'!F:F,"Success") -> 0 | G18: =AVERAGEIF('Raw Data'!D:D,"Provider_D",'Raw Data'!H:H) -> 13.884508 | I18: Germany | J18: 1823 | K18: 0.65112452 | L18: =COUNTIFS('Raw Data'!C:C,"Germany",'Raw Data'!I:I,1)/COUNTIFS('Raw Data'!C:C,"Germany",'Raw Data'!F:F,"Success") -> 0.0033698399 | M18: =COUNTIFS('Raw Data'!C:C,"Germany",'Raw Data'!M:M,1)/COUNTIFS('Raw Data'!C:C,"Germany") -> 0.050466264 | N18: =SUMIFS('Raw Data'!E:E,'Raw Data'!C:C,"Germany") -> 1003113.7
I19: Netherlands | J19: 401 | K19: 0.64588529 | L19: =COUNTIFS('Raw Data'!C:C,"Netherlands",'Raw Data'!I:I,1)/COUNTIFS('Raw Data'!C:C,"Netherlands",'Raw Data'!F:F,"Success") -> 0 | M19: =COUNTIFS('Raw Data'!C:C,"Netherlands",'Raw Data'!M:M,1)/COUNTIFS('Raw Data'!C:C,"Netherlands") -> 0.027431421 | N19: =SUMIFS('Raw Data'!E:E,'Raw Data'!C:C,"Netherlands") -> 203351.86
B20: 🏆 BEST: Provider_C — SR 73.4% | E20: ⚠️ WORST: Provider_D — SR 45.8% (Provider Outage Detected) | I20: Poland | J20: 1402 | K20: 0.68473609 | L20: =COUNTIFS('Raw Data'!C:C,"Poland",'Raw Data'!I:I,1)/COUNTIFS('Raw Data'!C:C,"Poland",'Raw Data'!F:F,"Success") -> 0 | M20: =COUNTIFS('Raw Data'!C:C,"Poland",'Raw Data'!M:M,1)/COUNTIFS('Raw Data'!C:C,"Poland") -> 0.027817404 | N20: =SUMIFS('Raw Data'!E:E,'Raw Data'!C:C,"Poland") -> 785832.56
I21: Portugal | J21: 910 | K21: 0.65934066 | L21: =COUNTIFS('Raw Data'!C:C,"Portugal",'Raw Data'!I:I,1)/COUNTIFS('Raw Data'!C:C,"Portugal",'Raw Data'!F:F,"Success") -> 0.0033333333 | M21: =COUNTIFS('Raw Data'!C:C,"Portugal",'Raw Data'!M:M,1)/COUNTIFS('Raw Data'!C:C,"Portugal") -> 0.034065934 | N21: =SUMIFS('Raw Data'!E:E,'Raw Data'!C:C,"Portugal") -> 513273.36
I22: Spain | J22: 1121 | K22: 0.65744871 | L22: =COUNTIFS('Raw Data'!C:C,"Spain",'Raw Data'!I:I,1)/COUNTIFS('Raw Data'!C:C,"Spain",'Raw Data'!F:F,"Success") -> 0.0013568521 | M22: =COUNTIFS('Raw Data'!C:C,"Spain",'Raw Data'!M:M,1)/COUNTIFS('Raw Data'!C:C,"Spain") -> 0.033006244 | N22: =SUMIFS('Raw Data'!E:E,'Raw Data'!C:C,"Spain") -> 632718.53
I23: Sweden | J23: 596 | K23: 0.64261745 | L23: =COUNTIFS('Raw Data'!C:C,"Sweden",'Raw Data'!I:I,1)/COUNTIFS('Raw Data'!C:C,"Sweden",'Raw Data'!F:F,"Success") -> 0.0052219321 | M23: =COUNTIFS('Raw Data'!C:C,"Sweden",'Raw Data'!M:M,1)/COUNTIFS('Raw Data'!C:C,"Sweden") -> 0.035234899 | N23: =SUMIFS('Raw Data'!E:E,'Raw Data'!C:C,"Sweden") -> 333637.8
I24: UK | J24: 1568 | K24: 0.64732143 | L24: =COUNTIFS('Raw Data'!C:C,"UK",'Raw Data'!I:I,1)/COUNTIFS('Raw Data'!C:C,"UK",'Raw Data'!F:F,"Success") -> 0.0039408867 | M24: =COUNTIFS('Raw Data'!C:C,"UK",'Raw Data'!M:M,1)/COUNTIFS('Raw Data'!C:C,"UK") -> 0.035076531 | N24: =SUMIFS('Raw Data'!E:E,'Raw Data'!C:C,"UK") -> 879664.39
I26: 🏆 BEST: Austria — SR 71.4% | L26: ⚠️ WORST: Brazil — SR 57.1%
B28: 🔍 ANOMALIES DETECTED — REQUIRES IMMEDIATE INVESTIGATION
B29: 🚨 CRITICAL | D29: Velocity Attack
B30: Player PL00001 made 25 deposits in 50 minutes (Germany/Provider_A). Card testing pattern detected. Risk Score: 80+. Recommend: immediate account freeze + BIN blacklist.
B31: 🚨 CRITICAL | D31: Chargeback Spike — Brazil
B32: 30 chargebacks from Brazil in June 2025 (vs avg 2-3/month). All via Provider_B, same BIN range 500000-559999. Possible coordinated Friendly Fraud attack. Recommend: geo-flag Brazil + Provider_B review.
B33: ⚠️ HIGH | D33: Provider_D Outage
B34: Provider_D Success Rate: 45.8% vs benchmark 65%+. Avg response time: 13.9s (normal <5s). Recommend: suspend Provider_D routing until SLA restored.
B35: ⚠️ HIGH | D35: Multi-Account Cluster
B36: 617 accounts flagged for multi-accounting (6.1% of traffic). Concentrated in Germany and UK. Likely Bonus Abuse coordination. Recommend: device fingerprint audit + bonus policy review.
B38: EXECUTIVE SUMMARY
B39: 📌 Overview
B40: Analysis of 10,055 iGaming transactions across 4 providers and 10 countries (Jan–Dec 2025). Total volume: €5,590,234. Overall Success Rate 64.9%, Approval Rate 75.6%. Dataset contains embedded fraud patterns for risk validation.
B41: 🏆 Provider Performance
B42: Provider_C leads with highest Success Rate. Provider_D is critically underperforming (45.8% SR, avg 13.9s response time) — consistent with a technical outage. Immediate routing suspension recommended.
B43: 🌍 Geographic Risk
B44: Best performing country: Austria (SR 71.4%). Brazil shows the highest chargeback concentration and fraud rate — likely coordinated Friendly Fraud. Recommend enhanced verification for Brazilian players.
B45: 💳 Chargeback & Fraud
B46: Overall Chargeback Ratio: 0.659%. 384 fraud flags detected (3.82% of traffic). Velocity attack pattern identified on Player PL00001. VPN usage at 8.6% — above typical 5% threshold. Additionally, 1,077 transactions were tagged with failure_reason column identifying provider-side timeouts and session abandonments for deeper root cause analysis.
...
